Workbook

Sheet objects
A1: Name | B1: Generation Method | C1: Description | D1: Purpose (Attribution) | E1: *Purpose (Analytics) | F1: Granularity | G1: Field Count | H1: generate? | I1: generation_order | J1: Generate_Rows | K1: existing consumption project | L1: bps_roi_rw | M1: extend the views/objects
A2: Campaigns | B2: Source System | C2: A group of marketing activities designed to support a specific business objective or overaching message. | D2: May be used to influence attribution wieghting as contains metadata that might indicate how relevant the content was for the linked outcome. | E2: Use for comparing campaign performance. Used for filtering to activity within a specific campaign or attribute of campaign. | F2: This is defined by the use of monday.com to generate a grouping. each Campaign should have a unique Monday Code. Iideally each campaign should have a clear and distinct audience. Be aligned to a single objective. We expect Asset reuse to be contained to a single campaign. Campaigns may superseed each other if there is a singificant overhall of content or delivery machanisms. In this case there would be multiple Rows representing each version of the campaign. | G2: =COUNTIF(Attributes!A:A,objects!A2) -> 18 | H2: y | I2: 1 | J2: 30 | L2: bps_roi_ro/DSS(Archect review Qlik)
A3: Channels | B3: MRD | C3: A method of Delivering Content/assets to customers. E.G. Email. | D3: May be used to generalise and estimate the proportion of outcomes attributed back to activity. | E3: Use for comparison and filtering on dashboards to compare between channels and compare within a channel. | F3: Each channel represents a different way the customer experiances recieving the Asset. This is a reference table So each channel should be agreed and defined, This should be technology agnostic from BT delivery method. But might be technology relevant for delivery platform, Where BT has control. That is each Social Media platform is a different channel, Within those Ads Vs Organic Would be a different channel. But within Email there wouldn’t be different channels for the different email clients a person may recieve an email with. | G3: =COUNTIF(Attributes!A:A,objects!A3) -> 6 | H3: Y | I3: 2 | J3: 10
A4: Facilitation Tool | B4: MRD | C4: A BT tool that facilitates the delivery of content/asssets to the Customers. | D4: Attribution shouldn’t use this information. | E4: Usefuly for Comparison and Filtering, So understand perfomance of similar channels and campaigns across different platforms. And to Understand within platforms performance. | F4: Each row Represents a single platform. This is a reference table. Some decisions need to be made as to how platform bundles and addons should be Represented. Suggest each row represents the complete tool. All the elements accessible from a single interface/Has a seperate contract/cost/Would be expected to be used by the same person. | G4: =COUNTIF(Attributes!A:A,objects!A4) -> 4 | H4: Y | I4: 3 | J4: 7
A5: Marketing Assets | B5: Source System | C5: This is a piece of content or experiance that would be expected to be engaged with at a single point in time. | D5: May be used to generalise and estimate the proportion of outcomes attributed back to activity. | E5: Useful for comparison within a particular channel to find find grain improvements | F5: Each Row Represents a single piece of content, This may be an email, article, event. Some channel specific examples. Short events / Webinars might be one asset, Longer Events may be split into session. Variations of an email that share a meaningfully different message would be seperate assets. But emails that differ only in personalisation changes would be one asset. An assets should be something that everyone experiances the same way. No two people should have meaningfully different experiances with that asset. | G5: =COUNTIF(Attributes!A:A,objects!A5) -> 9 | H5: Y | I5: 4 | J5: 300
A6: Audience | B6: Source System | C6: A set of chriteria that defined a group of people who might be targeted for a communication or may be expected to be influenced by an asset. | D6: Purpose here is to provide a linking methodology for Assets where direct influence to individuals is not possible due to the delivery channel. | E6: Not used for Analytics | F6: A specific and complete set of criteria would be contained in a single row. This same audience may be utilised by multiple assets or channels. This wouldn’t result in multiple Audience rows. Multiple audiences criteria may have overlapping members. And audience respresents the complete criteria a communicatino wouldn’t go to some intersection of two audiences, This example would be a third audience. | G6: =COUNTIF(Attributes!A:A,objects!A6) -> 8 | H6: Y | I6: 5 | J6: 100
A7: Marketing Activity | B7: Source System | C7: Outbound, proactive, targeted distribution of marketing assets (e.g., emails, calls, direct mail). Or Organic, content-driven strategies that attract and engage audiences on their own terms (e.g., social posts, billboards, website content). | D7: This Identifies the actions that BT Carries out and is ultimately the most granular element of Marketing activity that BT can optimise. | E7: Again this is a baseline for the marketing activity that has been carried out by BT. | F7: Each Row represents the Sending of a single assets to a single contact point which may be an individual or company. This is based on the experiance of the reciepient, So technical retries due to failure wouldn’t result in multiple rows, But if the User recieved two duplicate messages at the same time this would be 2 seperate rows. This covers everyone who was selected in the audience to receive the communication, Including the Control Cell audience. OR Each Row represents a BT action to any number of people. Each action should have a Time or a timeframe where it would be consistantly showing the same asset. Given the audience is Unknown one row here might have multiple engagements from Multiple Individuals or Companies. | G7: =COUNTIF(Attributes!A:A,objects!A7) -> 18 | H7: y | I7: 15 | J7: 10000
A8: Interactions | B8: Source System | C8: Tracked activities by individuals that show they are engaging with an Asset. | D8: This Justifies that the marketing activity was engaged with by the individual and so supports the implication that thier buying decision was influenced by the result. Greater strength of interaction with marketing activity can be used for increased attribution of outcome to that activity. | E8: This may be used for more targeted and channel specific assets engagement reporting. | F8: Each row links one person to one activity. There may be multiple interactions for a person to an Activity | G8: =COUNTIF(Attributes!A:A,objects!A8) -> 10 | H8: y | I8: 17 | J8: 500000
A9: Attribution Linking Table | B9: Derived | C9: The cross reference table between the Marketing Activity and Outcome Tables. | D9: This contains the raw relationships that could be attributed. | E9: Not useful for Other Analytical purposes. | F9: Each Row represents the relationship between an outcome and an activity for a Given model. | G9: =COUNTIF(Attributes!A:A,objects!A9) -> 9 | H9: Y | I9: 18
A10: Person | B10: Source System | C10: This contains all information related to an individual who is a customer or prospect | D10: Used as part of the linking chain for activities through to outcomes. Person attributes may contribute to external factors for weighting of attribution. | E10: May be used for non attribution analytics looking at specific person activity. Useful for specific attribution investigation and validation. | F10: To be decided, Might be outside the scope of this project to resolve person identities. Suggested initially maintain the grain of the source systems person objects. So a Row represents one marketo person record,… | G10: =COUNTIF(Attributes!A:A,objects!A10) -> 5 | H10: y | I10: 7 | J10: 5000
A11: Company | B11: Source System | C11: This represents a company entity at potentially multiple grains. | D11: Used as part of the linking chain for activities through to outcomes. People link to a company, Outcomes link to a company, Companies link to other companies through thier hierachy. Company attributes may contribute to external factors for weighting of attribution. | E11: May be used for non attribution analytics looking at specific company activity. Useful for specific attribution investigation and validation. | F11: Each Row represents on company object at a specific BT grain, I.E. CUG or Billing Account,… These objects would have self hierarchicle relationships that links for example billing accounts to CUGs. So there would be a row for each billing account then a seperate row for each CUG,… The MDM project may result in a more standardised object being available. At which point it may be that all activity and Outcomes can be standardised to a specific grain. | G11: =COUNTIF(Attributes!A:A,objects!A11) -> 8 | H11: y | I11: 6 | J11: 3000
A12: Person Company Role | B12: Source System | C12: Represents the relationship a person has with a company. I.E. decision maker, influences. Enables the concept of a person have relationships with multiple companies. | D12: Used as part of the linking of activity to outcome. Role used for attribution wieghting and filtering. | E12: Useful for other non attribution analytical views. | F12: Each row represents a the role a person has with a company. The same person may be linked to the same company multiple times with different roles. this would be multiple rows. | G12: =COUNTIF(Attributes!A:A,objects!A12) -> 5 | H12: Y | I12: 8
A13: Orders | B13: Source System | C13: Point in Time revenue generating events related to a specific company and product. | D13: This is an outcome to be attributed to influence activities. | E13: Used to show the attributed outcomes | F13: Each Row should be a single product, sold at a specific point in time, to a specific company. Order of multiple units could be grouped to a single row. Mutiple different products sold at the same time to the same company as part of a single purchase event should still be different rows. | G13: =COUNTIF(Attributes!A:A,objects!A13) -> 24 | H13: y | I13: 9 | J13: 7000
A14: Opportunities | B14: Source System | C14: The Opportunity to have a sales focussed discussion/process with an individual to sell a specific product, group of products, or package. With an end success for failure result. | D14: This is an outcome to be attributed to influence activities. | E14: Used to show the attributed outcomes | F14: Each Row represents a period of time attempting to sell a to a specific interest for a specific company. This should end in a success or failure. A Second row could represent a further attempt to sell to the same interest to the same company at a different time. E.g. Each yearly renewal. Multiple individuals can be involved with a single opportunity this would be 1 row. Two distinct groups of individuals E.G. different local decision makers at different sites, Could be seperate rows for the same interest at the same company. If it was possible for these to have different outcomes. An Opportunity could be selling multiple Products. Ultimately this should match the current in system opportunity grain. | G14: =COUNTIF(Attributes!A:A,objects!A14) -> 0 | H14: n | I14: 10
A15: Customer Value Change | B15: Logic to be derived | C15: Point in time changes in customer value taking into account all product/Subscription changes happening at that account. | D15: This is an outcome to be attributed to influence activities. | E15: Used to show the attributed outcomes | F15: Each Row represents a company and a time period for that company, Showing its value change. There should be no overlapping of time periods for that company. Suggestion this is grouped to a monthly time period. I.E. each row represents the value change for a company over a month. If there was no value change then no row needs to exist. | G15: =COUNTIF(Attributes!A:A,objects!A15) -> 11 | H15: n | I15: 11
A16: Retention | B16: Logic to be derived | C16: Point in Time where companies started & cease to be a customer of BT. | D16: This is an outcome to be attributed to influence activities. | E16: Used to show the attributed outcomes | F16: Each Row represents the point in time that a company changed its status as a customer with each BT Brand. If a company leaves and rejoins and leaves again there would be multiple rows for each of these events. If a company leaves as a BT and EE customer there would be two seperate rows for these events. | G16: =COUNTIF(Attributes!A:A,objects!A16) -> 0 | H16: n | I16: 12
A17: Attribution Model Output Table | B17: Data Science Team | C17: Percentages that a model has assigned as the impact of a marketing activity to an outcome. | D17: This is the Main output for the attribution modelling | E17: Core to all attribution metrics | F17: Each Row represents a single marketing activity linked to a single outcome for a particular model. There may be multiple models that have assigned different attribution levels for the same marketing activity to the same outcome element. Within a single model there would neven be multiple entries for the same marketing activity and outcome element interaction. Not every marketing activity will be linked to event outcome element. | G17: =COUNTIF(Attributes!A:A,objects!A17) -> 4 | H17: n | I17: 14
A18: Attribution Model | B18: Data Science Team | C18: Description of the Model and Run parameters | D18: This is suplimentary information to the main output for the attribution modelling. | E18: Used to manage and identify which model should be used in which circumstance and when models should no longer be shown in the dashboarding views. | F18: Each Row represents an different model or iteration of a model. Model iterations would be where all the data has been recalculated with some meaningful change to input parameters. | G18: =COUNTIF(Attributes!A:A,objects!A18) -> 0 | H18: n | I18: 13
A19: Products | B19: Source System | C19: Describes the BT Product Catelogue at different levels and contains the hierachy of products | D19: Enables linking of both marketing activity and outcomes to the same products for relevance matching. | E19: Used for comparing and filtering across all levels. | F19: Each Row represents a product or group or family, All levels of heirachy are contained. | H19: Y | I19: 0
A20: Date Dimension | B20: Derived | C20: Calendar Table that contains all dates, For a unified reference. Expecting something like this already exists close to other analytics use cases. | D20: Used for Date difference calculations and core attribution logic matching | E20: Dashboard Filtering and timeline Dimensions | F20: Each Row Represents a Day | H20: Y | I20: 0

Sheet Attributes
A1: Object | B1: Name | C1: Description | D1: Purpose(modelling) | E1: Purpose(Analytics) | F1: Format | G1: Example Values | H1: Tokenised | I1: Tokenised Reason | J1: Requirement
A2: Attribution Linking Table | B2: link_id | C2: Unique Identifier for this particular link | F2: PK
A3: Attribution Linking Table | B3: activity_id | C3: Identifies the specific marketing activity being linked | F3: FK -> Activity.Activity_ID
A4: Attribution Linking Table | B4: interaction_id | C4: Identifies the specific interaction that is being linked | F4: FK -> Interaction.Interaction_ID
A5: Attribution Linking Table | B5: outcome_type | C5: Identifies which outcome table is being linked | F5: Picklist
A6: Attribution Linking Table | B6: outcome_id | C6: Identifies the specific outcome within that table that is linked. | F6: FK -> Outcome_Type.Outcome_ID
A7: Attribution Linking Table | B7: company_id | C7: Identifies the company that carried out the interaction and is related to the outcome. | F7: FK -> Company.Company_ID
A8: Attribution Linking Table | B8: person_id | C8: Identifies the Person related to the activity or interaction. | F8: FK -> Person.Person_ID
A9: Attribution Linking Table | B9: relation_type | C9: Classify how the Activity was related to the outcome. Its possible there were multiple methods to associate the activity with the outcome. This identifies the most confident of linkage types. | F9: Picklist | G9: Direct - Activity can be directly linked to the outcome I.E. they bought on the call. Known Person - The person that carried out the interaction/was targeted by activity is linked to the company that had the outcome. Known company - The company that was targeted by activity or carried out the interaction could be confidently identified and that company is linked to the outcome. Inferred company - The activity was likely carried out be the company that is linked to the activity. Inferred via Audience - The individual / company was included in the audience for the marketing activity.
A10: Attribution Linking Table | B10: time_lag | C10: Time Between the Activity and the outcome * modelling may prefer to calculate from source fields. | F10: Time Difference
A11: Attribution Model Output Table | B11: model_output_id | C11: Unique Identifier for the model output given for this link and model. | F11: ID - PK
A12: Attribution Model Output Table | B12: link_id | C12: Which is the link this result relates to | F12: ID - FK
A13: Attribution Model Output Table | B13: model_id | C13: Which Model has provided this result | F13: ID - FK
A14: Attribution Model Output Table | B14: attribution_weight | C14: What is the proportion of the outcome that was caused by the activity as calculated by the model. | F14: Float | G14: 0.05
A15: Attrribution Model | B15: model_id | C15: Unique Identifier for the model | F15: ID - PK
A16: Attrribution Model | B16: model_name | C16: Name given the the model | F16: String | G16: V01.0_Rules_Based_with_Guardrails
A17: Attrribution Model | B17: model_start_date | C17: When was the model usable from | F17: Date
A18: Attrribution Model | B18: model_end_date | C18: When does the model cease to be useable. | F18: Date
A19: Attrribution Model | B19: model_status | C19: is the model validated and usable, or retired | F19: Picklist
A20: Attrribution Model | B20: model_type | C20: Classifies the models that are produced by the modelling team by which techniques they use | D20: Output from the modelling team | E20: Used to allow end users to select the appropriate model and understand at a high level how that model is approaching attribution. | F20: Picklist | G20: Rules based, learned, TBC from Modelling Team
A21: Attrribution Model | B21: outcome_used | C21: Which outcome is this model Attributing for | F21: Picklist | G21: Raised Orders, Completed Orders, Customer Value Change, Churn, leads, Lead Conversion
A22: Attrribution Model | B22: model_owner | C22: Current Owner of the model implimentation | F22: String | G22: Petros
A23: Campaigns | B23: campaign_id | C23: Primary Identified for a campaign, This could either be the Monday code or a GCP generated ID, using the Monday code as a proxy identifier. | F23: ID - PK
A24: Campaigns | B24: campaign_name | C24: The Unique business understandable short name of the campaign. | F24: String
A25: Campaigns | B25: created_date | C25: Date the Campaign was created (in Monday.com) | F25: Date
A26: Campaigns | B26: start_date | C26: Date the campaign First went live and it was possible for a person to interact with the campaigns content. | F26: Date
A27: Campaigns | B27: end_date | C27: Date the campaign finished, the content is no longer being shared and new interactions are either impossible or unlikely. | F27: Date
A28: Campaigns | B28: budget_timeframe | C28: The Quarter? Budget that was allocated to the development and support of this campaign. TBC this may need to be a Multi Line/ separate object depending on data source. | D28: N/A - When budget was allocated shouldn't have any impact of overall campaign attribution | E28: Support Views look at Spend vs outcome for appropriate ROI analysis.
A29: Campaigns | B29: targeted_audience_id | C29: ** Might not be directly relevant might primarially be joined via the Activity | F29: FK -> Audience.Audience_ID
A30: Campaigns | B30: parent_campaign_id | C30: Identifies a parent campaign that might encompass multiple child campaigns. | D30: Modelling would focus on the lowest level of campaign | E30: For grouping and organisation of campaigns as well as handling roleup and agreegation to different levels. | F30: FK ->Campaigns.Campaign_ID
A31: Campaigns | B31: costs_anticipated | C31: Planned Cost of the campaign, How much of the budget has been provisionally allocated.
A32: Campaigns | B32: costs_actuals | C32: The actual tracked cost for this campaign. TBC if this is just external cost of if there is also an internal effort considered here.
A33: Campaigns | B33: outcome_targets | C33: Likely Multiple Fields, E.G. Expected uplift in order amounts. TBC with Monday.com setup what is available. | D33: N/A | E33: Visual to show actuals vs Targets Able to show which campaigns are performing below or above expectations.
A34: Campaigns | B34: brand | C34: Which Brand is the Campaign Representing | D34: Allow limiting or wieghting of attribution based on Brand matching between activity and outcome. | E34: Dimension for Filter / Comparison | G34: BT Business EE Business BT Consumer EE Consumer
A35: Campaigns | B35: business_unit | C35: Which Business Unit is the campaign Targeting | G35: SMB, CPS, Global
A36: Campaigns | B36: dmo_owner | C36: Or another table that identifies the roles associated with the campaign.
A37: Campaigns | B37: ???_owner | C37: Or another table that identifies the roles associated with the campaign.
A38: Campaigns | B38: product_id | C38: Identifies the Product the Campaign Is Targeting | F38: FK -> Product.Product_ID
A39: Campaigns | B39: objective | C39: What part of the customer lifecycle is being targeted | G39: Welcome Acquisition Upsell Cross-sell Retention In-Life Service Migration Out of Contract
A40: Campaigns | B40: partner | C40: Company that is partnering, supporting, or running the campaign. E.G. a Joint Event with a Vendor.
...

Sheet Sheet1
A1: Activity ID | B1: Outcome ID | C1: Outcome Type | D1: Link ID | E1: Interaction | F1: Contact | G1: Company | H1: Relation Type | I1: Time Lag (Days) | K1: Weight | M1: Outcome Value | N1: Attributed Amount | P1: Sales Order Value | Q1: Sales Order Value Gross Margin | R1: Initial Contract Value | S1: Initial Contract Value Gross margin | T1: Average Revenue per Unit
A2: 1 | B2: 1 | C2: Opportunty Created | D2: a | E2: 1 | F2: 1 | G2: 1 | H2: Direct Through Order | I2: 10 | K2: 0.1 | M2: 1000 | N2: =M2*K2 -> 100
A3: 1 | B3: 2 | C3: Opportunty Won | D3: b | E3: 1 | F3: 5 | G3: 2 | H3: Through Company | I3: 200 | K3: 0.02 | M3: 250 | N3: =M3*K3 -> 5
A4: 1 | B4: 2 | C4: Opportunty Won | D4: h | E4: 2 | G4: 3 | H4: Inferred company | I4: 15 | K4: 0.6 | M4: 250 | N4: =M4*K4 -> 150
A5: 2 | B5: 1 | C5: Opportunty Created | D5: c | E5: 3 | G5: 4 | H5: Through Contact & Company | I5: 1 | K5: 0.52 | M5: 1000 | N5: =M5*K5 -> 520
A6: 3 | B6: 3 | C6: Orders | D6: d | E6: 4 | F6: 6 | G6: 5 | H6: Through Company | I6: 0 | K6: 0.1 | M6: 555 | N6: =M6*K6 -> 55.5
A7: 4 | B7: 4 | C7: Orders | D7: e | F7: 5 | G7: 6 | H7: Inferred company | I7: 256 | K7: 0.001 | M7: 789 | N7: =M7*K7 -> 0.789
A8: 5 | B8: 7 | C8: Orders | D8: f | E8: 6 | G8: 7 | H8: Through Contact & Company | I8: 24 | K8: 0.001 | M8: 5 | N8: =M8*K8 -> 0.005
A9: 8 | B9: 8 | C9: Orders | D9: g | F9: 8 | G9: 8 | H9: Direct Through Order | I9: 51 | K9: 0.001 | M9: 1000000 | N9: =M9*K9 -> 1000

Sheet Aggregations and Calculations
A1: Name | B1: Dashboards | C1: Description | D1: Dependancies
A2: Total Conversions | C2: Count of desired actions (purchases, sign-ups, etc.).
A3: Conversion Rate | C3: (Conversions / Audience Size) × 100
A4: Time to Conversion | C4: Avg. days between first marketing touchpoint and conversion.
A5: Conversion Rate by Channel | C5: Conversions per channel / Total audience reached via that channel.
A6: Churn Rate | C6: (Customers Lost / Total Customers at Start of Period) × 100
A7: Marketing Impact on Churn | C7: Reduction in churn among customers exposed to marketing.
A8: Attributed Marketing Impact -
A9: Attributed Revenue per Channel | C9: Revenue from customers exposed to marketing per channel.
A10: Incremental Lift from Marketing | C10: (Conversion Rate of Exposed Group - Conversion Rate of Non-Exposed Group)
A11: Marketing Influence Score | C11: Weighted impact of different marketing touchpoints on final outcomes.
A12: Multi-Touch Attribution Value per Path | C12: Total attributed revenue divided by the % of conversions that followed a specific marketing sequence.
A13: Customer Segmentation & Behavioural Trends -
A14: Customer Lifetime Value (CLV) Banding | C14: Avg. revenue per customer over a defined period.
A15: Retention Rate by Audience Segment | C15: % of customers retained within each segment (e.g., industry, location, tenure).
A16: Most Common Engagement Paths | C16: Rank sequences of interactions that most often lead to conversion.
A17: Content Effectiveness Score | C17: Engagement rate per marketing asset (emails, ads, videos, etc.).
E18: Business Description | F18: Technical Description
A19: Outcome Timeframe | B19: All Outcomes, Product Outcomes, Audience Analysis | C19: This is the Time that the outcome is recognised by the business. Here we are interested in the Raised date for orders, For other outcomes which field to use will vary | E19: “This is the time that the outcome is recognized by the business. Here we are interested in the Raised date for orders. For other outcomes, which date field to use can vary.” | F19: Typically derived from the “raised date” (or similar) in the orders/outcomes data. Stored in a field like outcome_date or order_raised_date. Used as a filter on dashboards to constrain the timeframe of recognized outcomes.
A20: Business Segment | B20: All Outcomes, Product Outcomes, Audience Analysis, Marketing Impact, Channel Impact | C20: SMB, CPS | E20: “SMB, CPS” | F20: A categorical/lookup field indicating the segment classification for each account or lead (e.g., 'SMB', 'CPS'). Likely stored in a field like business_segment in your master account/customer table.
A21: Total Conversions | B21: ??? | C21: The Number of Accounts with Orders by the number of distinct accounts in the Audience. | D21: Orders, Distinct Accounts, Audience | E21: “The Number of Accounts with Orders by the number of distinct Accounts in the Audience.” | F21: A count of unique accounts that have placed an order divided by the total number of distinct accounts in the relevant audience. E.g., COUNT(DISTINCT account_id WHERE has_order=true) / COUNT(DISTINCT account_id). Often displayed as a raw count (“converted accounts”) or a rate (“conversion rate”).
A22: Total Outcome Order Value | B22: All Outcomes, Product Outcomes, Specific Company Analysis, Audience Analysis | C22: Sum of Total_SOV for all raised Orders | E22: “Sum of Total_SOV for all raised Orders.” | F22: Aggregates the sum of value across all orders in a given timeframe or segment. E.g., SUM(order_total_sov) from orders (filtered by timeframe).
A23: Total Outcome Customer Value Change | B23: All Outcomes, Product Outcomes, Specific Company Analysis, Audience Analysis | C23: Option 1: Value Change = Total_SOV - PREV_TOTAL_SOV Keep this for only new Renewal or changed orders. This is for the date that the new order is raised. Option 2: Value Change = Sum (Total_SOV) Where Raised date in Timeframe - Sum (Total_SOV) Where Ceased Date in Timeframe Relies on Ceased dates being correct, Also need to consider how raised but ultimately failed orders are considered. | E23: “(Option 1) Value Change = Total_SOV - PREV_TOTAL_SOV. (Option 2) Value Change = Sum(Total_SOV) where raised date in timeframe - Sum(Total_SOV) where ceased date in timeframe.” | F23: Tracks how a customer’s total service/order value changes over time (new vs. ceased). One approach is current_sov - previous_sov. Alternatively, measure new SOV raised minus SOV ceased in the timeframe. Store or compute from orders data (raised_date, ceased_date).
A24: Total Outcome Churn | B24: All Outcomes, Product Outcomes, Specific Company Analysis, Audience Analysis | C24: Churn could be at 3 levels Customer, Product Group, Specific Product. Specific Product Option 1: For a Customer (Billing Account Level) A churn on a date occurs when on the previous day there was at least on active product for that customer. But on the selected day there are no longer any active products for the particular product specified. Products that cease but there exists another product that is linked as a renewal even if its a different product. Would not count as a product level churn. Product Family As Above but here looking at all product for a customer within a product family, If the count of live products for a product family for a customer goes from 1>0 This is a churn event for this customer (BAN). Again exclude from this products where there is a linked renewal for a product even if in a different family. Customer For a customer (BAN) a Churn occurs on a date where the count of live products goes from 1>0. Outstanding Questions: - Which is the field for the ceased date | E24: “Churn could be at 3 levels: Customer, Product Group, Specific Product. A churn event occurs on a date if the count of live products goes from 1→0 with no renewal link.” | F24: You can measure churn events/amount by comparing active product records day-to-day. E.g., a product is “ceased” on date X if it was active the prior day. Product-level or family-level churn excludes renewals. Technically, you might store churn_date or compare active_product_count from t to t-1.
A25: Attributed Outcome Order Value Amount | B25: All Outcomes, Product Outcomes, Specific Company Analysis, Audience Analysis, Marketing Impact, Channel Impact, Campaign Impact, Marketing Technology Impact | C25: Sum (Total_SOV for raised orders * Attribute %) Apply the attributed Percentage reduction to each raised order then Sum these. | E25: “Sum (Total_SOV for raised orders * Attribute %). Apply the attributed percentage to each raised order, then sum.” | F25: For each order, multiply its order_value (Total_SOV) by the marketing attribution factor (e.g., 0.3 if 30% is attributed to marketing). Then sum across all orders in the timeframe or segment. Technically: SUM(order_value * marketing_attribution_pct).
A26: Attributed Outcome Order Value Percentage | B26: All Outcomes, Product Outcomes, Specific Company Analysis, Audience Analysis, Marketing Impact, Channel Impact, Campaign Impact, Marketing Technology Impact | C26: Aggregated (Attributed Outcome order values amount) / Agreegated (Outcome order value amount) This is likely to be different to the sum of the attributed percentages. As it might be that larger orders have a larger marketing attribution and so the total amount attributed to marketing is higher once order values are taken into account. Here the order value could be any of SOV, SOV_GM, ICV, ICV_GM. Suggest the dashboard has some sort of switcher to move between these. | E26: (Percentage of total order value that is attributed to marketing.) | F26: Calculated as (Attributed Outcome Order Value Amount / Total Outcome Order Value) * 100. For a given dimension or grouping, you might do: SUM(order_value * attribution_pct) / SUM(order_value) * 100.
A27: Attributed Outcome Customer Value Change £ | B27: All Outcomes, Product Outcomes, Specific Company Analysis, Audience Analysis, Marketing Impact, Channel Impact, Campaign Impact, Marketing Technology Impact | E27: (Similar to “Customer Value Change,” but restricted to the fraction attributed to marketing.) | F27: For each relevant account or order, take the “value change” and multiply by the attribution factor. E.g., SUM( (new_sov - old_sov) * marketing_attribution_pct ) for the relevant set of records.
A28: Attributed Outcome Customer Value Change Percentage | B28: All Outcomes, Product Outcomes, Specific Company Analysis, Audience Analysis, Marketing Impact, Channel Impact, Campaign Impact, Marketing Technology Impact | E28: (Ratio of marketing-attributed customer value change to total customer value change.) | F28: (Attributed Outcome Customer Value Change £ / Total Outcome Customer Value Change) * 100.
A29: Attributed Outcome Churn | B29: All Outcomes, Product Outcomes, Specific Company Analysis, Audience Analysis, Marketing Impact, Channel Impact, Campaign Impact, Marketing Technology Impact | E29: “Churn could be at 3 levels… and we apply marketing attribution factor (or logic) to see which portion is attributed to marketing.” | F29: If marketing is credited with preventing or partially causing churn, you might track the fraction of churn events or churn amounts “tied” to marketing. The exact logic depends on your attribution model—e.g., if marketing prevented churn, or if a missed marketing touch contributed to churn. This is more specialized and may or may not appear on the Channel/Campaign dashboards unless explicitly needed.
A30: Attributed Outcome Churn Percentage | B30: All Outcomes, Product Outcomes, Specific Company Analysis, Audience Analysis, Marketing Impact, Channel Impact, Campaign Impact, Marketing Technology Impact | E30: (Percentage of total churn that was attributed to marketing, or possibly the share that was prevented by marketing.) | F30: Computed similarly to “Attributed Outcome Churn,” but expressed as a percentage: (Attributed Churn / Total Churn) * 100, or “churn avoided.” Not explicitly listed in Channel/Campaign/Tech dashboards in the PPT, so typically remains in the “outcomes” or “audience” views.
A31: Marketing Activity Channel group | B31: All Outcomes, Product Outcomes, Specific Company Analysis, Audience Analysis, Marketing Impact, Channel Impact, Campaign Impact, Marketing Technology Impact | C31: Web, Social, Outbound Comms | E31: “Web, Social, Outbound Comms,” etc. | F31: A high-level grouping of channels used for marketing. Often stored in a dimension table or a field like channel_group (e.g., 'web', 'social', 'outbound'). Widely used across multiple dashboards as a dimension or filter.
A32: Marketing Activity Channel | B32: Product Outcomes, Marketing Impact, Channel Impact, Campaign Impact, Marketing Technology Impact | E32: (A more granular channel—e.g., Email, Paid Search, LinkedIn Ads, etc.) | F32: A detailed channel field in your campaign/activity logs, e.g., marketing_channel = 'email'. In your dashboards, you might roll this up into “channel group.”
A33: Outcome Product Family | B33: All Outcomes, Product Outcomes,Channel Impact | E33: (Groups outcome products into families—e.g., Mobile, Broadband, Security, etc.) | F33: A categorical or lookup field that classifies products. Typically in a product dimension table: product_family_id → 'Mobile', 'Hosting', 'Security', etc. Seen in multiple “outcome-focused” dashboards and also in Channel Impact (the PPT specifically references “Product Families” as a dimension).
A34: Outcome Product | B34: Product Outcomes, Specific Company Analysis, Channel Impact, Campaign Impact | E34: (The specific product sold, renewed, or churned.) | F34: Typically references the exact product in the outcome. E.g., a field outcome_product_id or order_product_code. Displayed in product-level dashboards, or in the “outcome products” dimension for Channel/Campaign Impact.
A35: Campaign Product Family | B35: Marketing Impact, Channel Impact | E35: (Indicates which product family the campaign is targeting or associated with—e.g., a “Mobile” campaign.) | F35: A lookup from the campaign record to the targeted product family. E.g., campaign_target_product_family_id → 'Mobile'. Explicitly in Marketing Impact and Channel Impact; can also be relevant in Campaign Impact or Tech Impact if you want to see the product families each campaign aims at.
A36: Transactions Channel | B36: All Outcomes, Product Outcomes | C36: How did they transact the order | E36: “How did they transact the order?” (online, phone, in-person, etc.) | F36: A field in the order data indicating the fulfillment/purchase channel. Often called something like transaction_channel. The PPT references “transactions channel” especially in outcome-focused dashboards.
A37: Outcome Type | B37: All Outcomes, Product Outcomes | C37: Acquisition, Resign, Cross-Sell | E37: “Acquisition, Resign, Cross-Sell.” | F37: A categorical field describing the type of outcome event. E.g., 'acquisition', 'resign', 'cross_sell'. Typically stored in outcome_type.
A38: Outcome Intentionality - Product | B38: All Outcomes, Product Outcomes | C38: *Did outcome product match marketing target product | E38: “Did the outcome product match the marketing target product?” | F38: A boolean or categorical field indicating if the actual product purchased (outcome) aligns with the intended product from the campaign. E.g.: outcome_product_id == campaign_target_product_id.
A39: Outcome Intentionality - Outcome Type | B39: All Outcomes, Product Outcomes | E39: (Checks if the type of outcome matched the intended outcome type—e.g., an Acquisition campaign yields an Acquisition outcome.) | F39: Another boolean or categorical field indicating if the outcome type (e.g., cross-sell) matches the campaign’s intended type. E.g.: IF campaign_objective = 'Cross-sell' AND outcome_type = 'cross_sell' THEN 'Intentional' ELSE 'Not Intentional'.
A40: Number of Campaigns | B40: Product Outcomes, Marketing Impact, Channel Impact, Marketing Technology Impact | E40: (A count of how many distinct campaigns were run or influenced the selected outcomes/timeframe.) | F40: Computed by counting distinct campaign_id across all relevant records. E.g.: COUNT(DISTINCT campaign_id). PPT explicitly mentions “# of campaigns run” in Product Outcomes, Marketing Impact, Channel Impact, and Marketing Technology dashboards.
...

Sheet Channels
A1: ID | B1: Name | C1: Group | D1: Identifiable method | E1: Type | F1: Comment
B2: Paid Digital Ads | C2: ATL | D2: IP Inferred
B3: Content Syndication | C3: ATL | D3: Audience Inferred
B4: Web | C4: ATL | D4: IP Inferred or Better
B5: Above the Line - Non Digital | C5: ATL | D5: Audience Inferred | F5: Placeholder For multiple channels
B6: Social Posts | C6: ATL | D6: Audience Inferred
B7: Social Outbound Messages | C7: BTL | D7: Known Person
B8: Virtual Events | C8: BTL | D8: Self Identified
B9: F2F Events | C9: BTL | D9: Self Identified
B10: Webinars | C10: BTL | D10: Self Identified
B11: Direct Mail | C11: BTL | D11: Known Person
B12: Whatsapp | C12: BTL | D12: Known Person
B13: RCS | C13: BTL | D13: Known Person
B14: Email | C14: BTL | D14: Known Person
B15: SMS | C15: BTL | D15: Known Person
B16: MMS | C16: BTL | D16: Known Person
B17: App Push Notification | C17: BTL | D17: Known Person
... B20: Sales Email | C20: Sales | D20: Known Person

Sheet Interaction Types
A1: Channel | B1: Interactions
A2: Paid Digital Ads | B2: Viewed | C2: Clicked | D2: Submit Form
A3: Content Syndication | B3: Viewed | C3: Clicked | D3: Submit Form
A4: Web | B4: Page View | C4: Link Click | D4: Submit Form | E4: Watch Video | F4: Download | G4: Live Chat?
A5: Above the Line - Non Digital | B5: Viewed
A6: Social Posts | B6: Viewed | C6: Clicked | D6: Responded
A7: Social Outbound Messages | B7: Viewed | C7: Clicked | D7: Responded | E7: Opt-Out
A8: Virtual Events | B8: Registered | C8: Attended | D8: View on Demand
A9: F2F Events | B9: Registered | C9: Attended
A10: Webinars | B10: Registered | C10: Attended | D10: View on Demand
A11: Direct Mail | B11: Sent | C11: Delivered | D11: Bounced
A12: Whatsapp | B12: Sent | C12: Received | D12: Read | E12: Clicked | F12: Responded | G12: Opt-Out
A13: RCS | B13: Sent | C13: Received | D13: Read | E13: Clicked | F13: Responded | G13: Opt-Out
A14: Email | B14: Sent | C14: Received | D14: Bounced | E14: Opened | F14: Clicked | G14: Opt-Out | H14: Responded
A15: SMS | B15: Sent | C15: Received | D15: Bounced | E15: Clicked | F15: Responsed | G15: Opt-Out
A16: MMS | B16: Sent | C16: Received | D16: Bounced | E16: Clicked | F16: Responsed | G16: Opt-Out
A17: App Push Notification | B17: Sent | C17: Received | E17: Clicked
A18: Sales Meetings | B18: Invited | C18: Attended
A19: Sales Calls | B19: Dialled | C19: Answered | D19: Engaged
A20: Sales Email | B20: Sent | C20: Received | D20: Bounced | E20: Opened | F20: Clicked | G20: Opt-Out | H20: Responded
A21: Inbound Calls | B21: Called
