Workbook

Sheet objects
A1: Name | B1: Generation Method | C1: Description | D1: Purpose (Attribution) | E1: *Purpose (Analytics) | F1: Granularity | G1: Field Count | H1: generate? | I1: generation_order | J1: Generate_Rows | K1: existing consumption project | L1: bps_roi_rw | M1: extend the views/objects | N1: Phase | O1: Order
A2: Interactions | B2: Source System | C2: Tracked activities by individuals that show they are engaging with an Asset. | D2: This Justifies that the marketing activity was engaged with by the individual and so supports the implication that thier buying decision was influenced by the result. Greater strength of interaction with marketing activity can be used for increased attribution of outcome to that activity. | E2: This may be used for more targeted and channel specific assets engagement reporting. | F2: Each row links one person to one activity. There may be multiple interactions for a person to an Activity | G2: =COUNTIF(Attributes!A:A,objects!A8) -> 17 | H2: y | I2: 17 | J2: 500000 | N2: MVP-1 | O2: 1
A3: Marketing Activity | B3: Source System | C3: Outbound, proactive, targeted distribution of marketing assets (e.g., emails, calls, direct mail). Or Organic, content-driven strategies that attract and engage audiences on their own terms (e.g., social posts, billboards, website content). | D3: This Identifies the actions that BT Carries out and is ultimately the most granular element of Marketing activity that BT can optimise. | E3: Again this is a baseline for the marketing activity that has been carried out by BT. | F3: Each Row represents the Sending of a single assets to a single contact point which may be an individual or company. This is based on the experiance of the reciepient, So technical retries due to failure wouldn’t result in multiple rows, But if the User recieved two duplicate messages at the same time this would be 2 seperate rows. This covers everyone who was selected in the audience to receive the communication, Including the Control Cell audience. OR Each Row represents a BT action to any number of people. Each action should have a Time or a timeframe where it would be consistantly showing the same asset. Given the audience is Unknown one row here might have multiple engagements from Multiple Individuals or Companies. | G3: =COUNTIF(Attributes!A:A,objects!A7) -> 0 | H3: y | I3: 15 | J3: 10000 | N3: MVP-1 | O3: 2
A4: Orders | B4: Source System | C4: Point in Time revenue generating events related to a specific company and product. | D4: This is an outcome to be attributed to influence activities. | E4: Used to show the attributed outcomes | F4: Each Row should be a single product, sold at a specific point in time, to a specific company. Order of multiple units could be grouped to a single row. Mutiple different products sold at the same time to the same company as part of a single purchase event should still be different rows. | G4: =COUNTIF(Attributes!A:A,objects!A13) -> 4 | H4: y | I4: 9 | J4: 70000 | N4: MVP-1 | O4: 3
A5: Person | B5: Source System | C5: This contains all information related to an individual who is a customer or prospect | D5: Used as part of the linking chain for activities through to outcomes. Person attributes may contribute to external factors for weighting of attribution. | E5: May be used for non attribution analytics looking at specific person activity. Useful for specific attribution investigation and validation. | F5: To be decided, Might be outside the scope of this project to resolve person identities. Suggested initially maintain the grain of the source systems person objects. So a Row represents one marketo person record,… | G5: =COUNTIF(Attributes!A:A,objects!A10) -> 4 | H5: y | I5: 7 | J5: 50000 | N5: MVP-1 | O5: 4
A6: Company | B6: Source System | C6: This represents a company entity at potentially multiple grains. | D6: Used as part of the linking chain for activities through to outcomes. People link to a company, Outcomes link to a company, Companies link to other companies through thier hierachy. Company attributes may contribute to external factors for weighting of attribution. | E6: May be used for non attribution analytics looking at specific company activity. Useful for specific attribution investigation and validation. | F6: Each Row represents on company object at a specific BT grain, I.E. CUG or Billing Account,… These objects would have self hierarchicle relationships that links for example billing accounts to CUGs. So there would be a row for each billing account then a seperate row for each CUG,… The MDM project may result in a more standardised object being available. At which point it may be that all activity and Outcomes can be standardised to a specific grain. | G6: =COUNTIF(Attributes!A:A,objects!A11) -> 34 | H6: y | I6: 6 | J6: 30000 | N6: MVP-1 | O6: 4
A7: Person Company Role | B7: Source System | C7: Represents the relationship a person has with a company. I.E. decision maker, influences. Enables the concept of a person have relationships with multiple companies. | D7: Used as part of the linking of activity to outcome. Role used for attribution wieghting and filtering. | E7: Useful for other non attribution analytical views. | F7: Each row represents a the role a person has with a company. The same person may be linked to the same company multiple times with different roles. this would be multiple rows. | G7: =COUNTIF(Attributes!A:A,objects!A12) -> 5 | H7: N | I7: 8 | J7: Dependant | O7: 4
A8: Attribution Linking Table | B8: Derived | C8: The cross reference table between the Marketing Activity and Outcome Tables. | D8: This contains the raw relationships that could be attributed. | E8: Not useful for Other Analytical purposes. | F8: Each Row represents the relationship between an outcome and an activity for a Given model. | G8: =COUNTIF(Attributes!A:A,objects!A9) -> 8 | H8: Y | I8: 18 | J8: Dependant | N8: MVP-1 | O8: 5
A9: Products | B9: Source System | C9: Describes the BT Product Catelogue at different levels and contains the hierachy of products | D9: Enables linking of both marketing activity and outcomes to the same products for relevance matching. | E9: Used for comparing and filtering across all levels. | F9: Each Row represents a product or group or family, All levels of heirachy are contained. | G9: =COUNTIF(Attributes!A:A,objects!A19) -> 0 | H9: Y | I9: 0 | N9: MVP-1 | O9: 6
A10: Attribution Model Output Table | B10: Data Science Team | C10: Percentages that a model has assigned as the impact of a marketing activity to an outcome. | D10: This is the Main output for the attribution modelling | E10: Core to all attribution metrics | F10: Each Row represents a single marketing activity linked to a single outcome for a particular model. There may be multiple models that have assigned different attribution levels for the same marketing activity to the same outcome element. Within a single model there would neven be multiple entries for the same marketing activity and outcome element interaction. Not every marketing activity will be linked to event outcome element. | G10: =COUNTIF(Attributes!A:A,objects!A17) -> 0 | H10: Y | I10: 19 | J10: Dependant | N10: MVP-1 | O10: 7
A11: Campaigns | B11: Source System | C11: A group of marketing activities designed to support a specific business objective or overaching message. | D11: May be used to influence attribution wieghting as contains metadata that might indicate how relevant the content was for the linked outcome. | E11: Use for comparing campaign performance. Used for filtering to activity within a specific campaign or attribute of campaign. | F11: This is defined by the use of monday.com to generate a grouping. each Campaign should have a unique Monday Code. Iideally each campaign should have a clear and distinct audience. Be aligned to a single objective. We expect Asset reuse to be contained to a single campaign. Campaigns may superseed each other if there is a singificant overhall of content or delivery machanisms. In this case there would be multiple Rows representing each version of the campaign. | G11: =COUNTIF(Attributes!A:A,objects!A2) -> 13 | H11: y | I11: 1 | J11: 30 | L11: bps_roi_ro/DSS(Archect review Qlik) | N11: MVP-2
A12: Channels | B12: MRD | C12: A method of Delivering Content/assets to customers. E.G. Email. | D12: May be used to generalise and estimate the proportion of outcomes attributed back to activity. | E12: Use for comparison and filtering on dashboards to compare between channels and compare within a channel. | F12: Each channel represents a different way the customer experiances recieving the Asset. This is a reference table So each channel should be agreed and defined, This should be technology agnostic from BT delivery method. But might be technology relevant for delivery platform, Where BT has control. That is each Social Media platform is a different channel, Within those Ads Vs Organic Would be a different channel. But within Email there wouldn’t be different channels for the different email clients a person may recieve an email with. | G12: =COUNTIF(Attributes!A:A,objects!A3) -> 17 | H12: Y | I12: 2 | J12: =COUNTA(Channels!B:B)-1 -> 22 | N12: MVP-2
A13: Facilitation Tool | B13: MRD | C13: A BT tool that facilitates the delivery of content/asssets to the Customers. | D13: Attribution shouldn’t use this information. | E13: Usefuly for Comparison and Filtering, So understand perfomance of similar channels and campaigns across different platforms. And to Understand within platforms performance. | F13: Each row Represents a single platform. This is a reference table. Some decisions need to be made as to how platform bundles and addons should be Represented. Suggest each row represents the complete tool. All the elements accessible from a single interface/Has a seperate contract/cost/Would be expected to be used by the same person. | G13: =COUNTIF(Attributes!A:A,objects!A4) -> 29 | H13: Y | I13: 3 | J13: 7
A14: Marketing Assets | B14: Source System | C14: This is a piece of content or experiance that would be expected to be engaged with at a single point in time. | D14: May be used to generalise and estimate the proportion of outcomes attributed back to activity. | E14: Useful for comparison within a particular channel to find find grain improvements | F14: Each Row Represents a single piece of content, This may be an email, article, event. Some channel specific examples. Short events / Webinars might be one asset, Longer Events may be split into session. Variations of an email that share a meaningfully different message would be seperate assets. But emails that differ only in personalisation changes would be one asset. An assets should be something that everyone experiances the same way. No two people should have meaningfully different experiances with that asset. | G14: =COUNTIF(Attributes!A:A,objects!A5) -> 59 | H14: Y | I14: 4 | J14: 300 | N14: MVP-2
A15: Audience | B15: Source System | C15: A set of chriteria that defined a group of people who might be targeted for a communication or may be expected to be influenced by an asset. | D15: Purpose here is to provide a linking methodology for Assets where direct influence to individuals is not possible due to the delivery channel. | E15: Not used for Analytics | F15: A specific and complete set of criteria would be contained in a single row. This same audience may be utilised by multiple assets or channels. This wouldn’t result in multiple Audience rows. Multiple audiences criteria may have overlapping members. And audience respresents the complete criteria a communicatino wouldn’t go to some intersection of two audiences, This example would be a third audience. | G15: =COUNTIF(Attributes!A:A,objects!A6) -> 42 | H15: Y | I15: 5 | J15: 100
A16: Opportunities | B16: Source System | C16: The Opportunity to have a sales focussed discussion/process with an individual to sell a specific product, group of products, or package. With an end success for failure result. | D16: This is an outcome to be attributed to influence activities. | E16: Used to show the attributed outcomes | F16: Each Row represents a period of time attempting to sell a to a specific interest for a specific company. This should end in a success or failure. A Second row could represent a further attempt to sell to the same interest to the same company at a different time. E.g. Each yearly renewal. Multiple individuals can be involved with a single opportunity this would be 1 row. Two distinct groups of individuals E.G. different local decision makers at different sites, Could be seperate rows for the same interest at the same company. If it was possible for these to have different outcomes. An Opportunity could be selling multiple Products. Ultimately this should match the current in system opportunity grain. | G16: =COUNTIF(Attributes!A:A,objects!A14) -> 9 | H16: n | I16: 10 | N16: MVP-2
A17: Customer Value Change | B17: Logic to be derived | C17: Point in time changes in customer value taking into account all product/Subscription changes happening at that account. | D17: This is an outcome to be attributed to influence activities. | E17: Used to show the attributed outcomes | F17: Each Row represents a company and a time period for that company, Showing its value change. There should be no overlapping of time periods for that company. Suggestion this is grouped to a monthly time period. I.E. each row represents the value change for a company over a month. If there was no value change then no row needs to exist. | G17: =COUNTIF(Attributes!A:A,objects!A15) -> 8 | H17: n | I17: 11 | N17: Dropped From Scope
A18: Retention | B18: Logic to be derived | C18: Point in Time where companies started & cease to be a customer of BT. | D18: This is an outcome to be attributed to influence activities. | E18: Used to show the attributed outcomes | F18: Each Row represents the point in time that a company changed its status as a customer with each BT Brand. If a company leaves and rejoins and leaves again there would be multiple rows for each of these events. If a company leaves as a BT and EE customer there would be two seperate rows for these events. | G18: =COUNTIF(Attributes!A:A,objects!A16) -> 16 | H18: n | I18: 12 | N18: Dropped From Scope
A19: Attribution Model | B19: Data Science Team | C19: Description of the Model and Run parameters | D19: This is suplimentary information to the main output for the attribution modelling. | E19: Used to manage and identify which model should be used in which circumstance and when models should no longer be shown in the dashboarding views. | F19: Each Row represents an different model or iteration of a model. Model iterations would be where all the data has been recalculated with some meaningful change to input parameters. | G19: =COUNTIF(Attributes!A:A,objects!A18) -> 0 | H19: Y | I19: 13 | J19: 1 | N19: MVP-2
A20: Date Dimension | B20: Derived | C20: Calendar Table that contains all dates, For a unified reference. Expecting something like this already exists close to other analytics use cases. | D20: Used for Date difference calculations and core attribution logic matching | E20: Dashboard Filtering and timeline Dimensions | F20: Each Row Represents a Day | G20: =COUNTIF(Attributes!A:A,objects!A20) -> 7 | H20: Y | I20: 0 | N20: MVP-2
A21: Outcome Change Set | B21: Derived | C21: This is a group of orders for a customer that are grouped as related | D21: Not Used For Attribution | E21: Used for reporting grouping CVC at a customer level and giving additional context to Attribution effects. | G21: =COUNTIF(Attributes!A:A,objects!A21) -> 0 | H21: n | N21: MVP-2
A22: Campaign Company membership | B22: Source System | C22: This identifies the Companies that are part of a campaign and those that are part of control cells for the campaign | D22: Needed for model tuning to align to control cell results analysis and inform model parameter choices | E22: Needed to showcase the Control Cell results within dashboarding. | F22: Each row represents a companies relationship with a campaign. Be that as a member or part of the control cell. | G22: =COUNTIF(Attributes!A:A,objects!A22) -> 8 | H22: n | N22: MVP-2
A23: Campaign Spend | B23: Source System | C23: Gives the costs associated with each campaign | D23: No Used for Attribution | E23: Allows for calculating the investment part of ROI | F23: each row represents a specific spend request for a campaign. | H23: Y

Sheet Attributes
A1: Object | B1: Name | C1: Description | D1: Purpose(modelling) | E1: Purpose(Analytics) | F1: Format | G1: Example Values | H1: Tokenised | I1: Tokenised Reason | J1: Required for POC? | K1: Requiered for MVP? | L1: Available in Core_Orders? | M1: Last Changed Date | N1: Change Description | O1: Column1
A2: Attribution Linking Table | B2: link_id | C2: Unique Identifier for this particular link | F2: PK | J2: MVP | M2: 45937 | N2: Set as PK | O2: =_xlfn.XLOOKUP(Table1[[#This Row],[Name]],'Field name checks'!A:A,'Field name checks'!A:A,"Missing",0) -> Missing
A3: Attribution Linking Table | B3: marketing_activity_id | C3: Identifies the specific marketing activity being linked | F3: FK -> Marketing Activity.Marketing_Activity_ID | J3: MVP | M3: 45947 | N3: Changed Name to marekting activity ID | O3: =_xlfn.XLOOKUP(Table1[[#This Row],[Name]],'Field name checks'!A:A,'Field name checks'!A:A,"Missing",0) -> Missing
A4: Attribution Linking Table | B4: interaction_id | C4: Identifies the specific interaction that is being linked | F4: FK -> Interaction.Interaction_ID | J4: MVP | O4: =_xlfn.XLOOKUP(Table1[[#This Row],[Name]],'Field name checks'!A:A,'Field name checks'!A:A,"Missing",0) -> Missing
A5: Attribution Linking Table | B5: outcome_type | C5: Identifies which outcome table is being linked | E5: used in metric calculations to filter out irrelevant rows. | F5: Picklist | G5: Order - Provide Order - Resign Order - Mixed Order - Churn Opportunity - Created Opportunity - Closed Won | J5: MVP | O5: =_xlfn.XLOOKUP(Table1[[#This Row],[Name]],'Field name checks'!A:A,'Field name checks'!A:A,"Missing",0) -> Missing
A6: Attribution Linking Table | B6: outcome_id | C6: Identifies the specific outcome within that table that is linked. | F6: FK -> Outcome_Type.Outcome_ID | J6: MVP | O6: =_xlfn.XLOOKUP(Table1[[#This Row],[Name]],'Field name checks'!A:A,'Field name checks'!A:A,"Missing",0) -> Missing
A7: Attribution Linking Table | B7: company_id | C7: Identifies the company that carried out the interaction and is related to the outcome. | F7: FK -> Company.Company_ID | J7: MVP | O7: =_xlfn.XLOOKUP(Table1[[#This Row],[Name]],'Field name checks'!A:A,'Field name checks'!A:A,"Missing",0) -> Missing
A8: Attribution Linking Table | B8: person_id | C8: Identifies the Person related to the activity or interaction. | F8: FK -> Person.Person_ID | J8: MVP | O8: =_xlfn.XLOOKUP(Table1[[#This Row],[Name]],'Field name checks'!A:A,'Field name checks'!A:A,"Missing",0) -> Missing
A9: Attribution Linking Table | B9: relation_type | C9: Classify how the Activity was related to the outcome. Its possible there were multiple methods to associate the activity with the outcome. This identifies the most confident of linkage types. | D9: Used as a paremeter to govern how much attribution is given to this link. | F9: Picklist | G9: Direct - Activity can be directly linked to the outcome I.E. they bought on the call. Known Person - The person that carried out the interaction/was targeted by activity is linked to the company that had the outcome. Known company - The company that was targeted by activity or carried out the interaction could be confidently identified and that company is linked to the outcome. Inferred company - The activity was likely carried out be the company that is linked to the activity. Inferred via Audience - The individual / company was included in the audience for the marketing activity. | J9: MVP | O9: =_xlfn.XLOOKUP(Table1[[#This Row],[Name]],'Field name checks'!A:A,'Field name checks'!A:A,"Missing",0) -> Missing
A10: Attribution Linking Table | B10: time_lag | C10: Time Between the Activity and the outcome * modelling may prefer to calculate from source fields. | D10: Used as a paremeter to govern how much attribution is given to this link. | F10: Time Difference | J10: MVP | O10: =_xlfn.XLOOKUP(Table1[[#This Row],[Name]],'Field name checks'!A:A,'Field name checks'!A:A,"Missing",0) -> Missing
A11: Attribution Linking Table | B11: product_yca_tier | C11: Identifiest the Tier of the product that is the closest common parent to the product of the order and the product of the Campaign or Asset. | D11: Used as a paremeter to govern how much attribution is given to this link. | E11: Not Relevant for analytics | F11: List of Values [Tiers} | J11: MVP | O11: =_xlfn.XLOOKUP(Table1[[#This Row],[Name]],'Field name checks'!A:A,'Field name checks'!A:A,"Missing",0) -> Missing
A12: Attribution Linking Table | B12: company_yca_type | C12: Gives the company_business_type of the Youngest Common Ancestor of the company the order was associated and the company assoicated to the activity. | D12: Used as a paremeter to govern how much attribution is given to this link. | E12: Not Relevant for analytics | F12: List of value [Company Types] | J12: MVP | O12: =_xlfn.XLOOKUP(Table1[[#This Row],[Name]],'Field name checks'!A:A,'Field name checks'!A:A,"Missing",0) -> Missing
A13: Attribution Model Output Table | B13: model_output_id | C13: Unique Identifier for the model output given for this link and model. | F13: ID - PK | J13: MVP | O13: =_xlfn.XLOOKUP(Table1[[#This Row],[Name]],'Field name checks'!A:A,'Field name checks'!A:A,"Missing",0) -> Missing
A14: Attribution Model Output Table | B14: link_id | C14: Which is the link this result relates to | F14: ID - FK | J14: MVP | O14: =_xlfn.XLOOKUP(Table1[[#This Row],[Name]],'Field name checks'!A:A,'Field name checks'!A:A,"Missing",0) -> Missing
A15: Attribution Model Output Table | B15: model_id | C15: Which Model has provided this result | F15: ID - FK | J15: MVP | O15: =_xlfn.XLOOKUP(Table1[[#This Row],[Name]],'Field name checks'!A:A,'Field name checks'!A:A,"Missing",0) -> Missing
A16: Attribution Model Output Table | B16: attribution_weight | C16: What is the proportion of the outcome that was caused by the activity as calculated by the model. | F16: Float | G16: 0.05 | J16: MVP | O16: =_xlfn.XLOOKUP(Table1[[#This Row],[Name]],'Field name checks'!A:A,'Field name checks'!A:A,"Missing",0) -> Missing
A17: Attrribution Model | B17: model_id | C17: Unique Identifier for the model | F17: ID - PK | J17: If Available | O17: =_xlfn.XLOOKUP(Table1[[#This Row],[Name]],'Field name checks'!A:A,'Field name checks'!A:A,"Missing",0) -> Missing
A18: Attrribution Model | B18: model_name | C18: Name given the the model | E18: Used to select which attribution model is used for attribution calculations | F18: String | G18: V01.0_Rules_Based_with_Guardrails | J18: If Available | O18: =_xlfn.XLOOKUP(Table1[[#This Row],[Name]],'Field name checks'!A:A,'Field name checks'!A:A,"Missing",0) -> Missing
A19: Attrribution Model | B19: model_start_date | C19: When was the model usable from | F19: Date | J19: If Available | O19: =_xlfn.XLOOKUP(Table1[[#This Row],[Name]],'Field name checks'!A:A,'Field name checks'!A:A,"Missing",0) -> Missing
A20: Attrribution Model | B20: model_end_date | C20: When does the model cease to be useable. | F20: Date | J20: If Available | O20: =_xlfn.XLOOKUP(Table1[[#This Row],[Name]],'Field name checks'!A:A,'Field name checks'!A:A,"Missing",0) -> Missing
A21: Attrribution Model | B21: model_status | C21: is the model validated and usable, or retired | E21: Used to confirm if this model is appropriate to use in Dashboarding. | F21: Picklist | J21: If Available | O21: =_xlfn.XLOOKUP(Table1[[#This Row],[Name]],'Field name checks'!A:A,'Field name checks'!A:A,"Missing",0) -> Missing
A22: Attrribution Model | B22: model_type | C22: Classifies the models that are produced by the modelling team by which techniques they use | D22: Output from the modelling team | E22: Used to allow end users to select the appropriate model and understand at a high level how that model is approaching attribution. | F22: Picklist | G22: Rules based, learned, TBC from Modelling Team | J22: If Available | O22: =_xlfn.XLOOKUP(Table1[[#This Row],[Name]],'Field name checks'!A:A,'Field name checks'!A:A,"Missing",0) -> Missing
A23: Attrribution Model | B23: outcome_used | C23: Which outcome is this model Attributing for | F23: Picklist | G23: Raised Orders, Completed Orders, Customer Value Change, Churn, leads, Lead Conversion | J23: If Available | O23: =_xlfn.XLOOKUP(Table1[[#This Row],[Name]],'Field name checks'!A:A,'Field name checks'!A:A,"Missing",0) -> Missing
A24: Attrribution Model | B24: model_owner | C24: Current Owner of the model implimentation | F24: String | G24: Petros | J24: If Available | O24: =_xlfn.XLOOKUP(Table1[[#This Row],[Name]],'Field name checks'!A:A,'Field name checks'!A:A,"Missing",0) -> Missing
A25: Audience | B25: audience_id | O25: =_xlfn.XLOOKUP(Table1[[#This Row],[Name]],'Field name checks'!A:A,'Field name checks'!A:A,"Missing",0) -> Missing
A26: Audience | B26: name | C26: Friendly Name of the audience | O26: =_xlfn.XLOOKUP(Table1[[#This Row],[Name]],'Field name checks'!A:A,'Field name checks'!A:A,"Missing",0) -> Missing
A27: Audience | B27: type | C27: How is this audience identified | O27: =_xlfn.XLOOKUP(Table1[[#This Row],[Name]],'Field name checks'!A:A,'Field name checks'!A:A,"Missing",0) -> Missing
A28: Audience | B28: audience_criteria_description | C28: An description of the requirements for the audience to fulfil | O28: =_xlfn.XLOOKUP(Table1[[#This Row],[Name]],'Field name checks'!A:A,'Field name checks'!A:A,"Missing",0) -> Missing
A29: Audience | B29: audience_criteria_technical | C29: The technical implimentation of these audience requirements. | O29: =_xlfn.XLOOKUP(Table1[[#This Row],[Name]],'Field name checks'!A:A,'Field name checks'!A:A,"Missing",0) -> Missing
A30: Audience | B30: propensity_model_used | C30: Identifies the propensity model that is used as part of the audience selection criteria. This would be a FK to another table. | D30: N/A | E30: Dimensions for filter and comparison, Gives the end user the ability to understand the effectiveness of the propensity models. | O30: =_xlfn.XLOOKUP(Table1[[#This Row],[Name]],'Field name checks'!A:A,'Field name checks'!A:A,"Missing",0) -> Missing
A31: Audience | B31: size_individuals | C31: The Estimated or actual count of individuals that form this audience. | O31: =_xlfn.XLOOKUP(Table1[[#This Row],[Name]],'Field name checks'!A:A,'Field name checks'!A:A,"Missing",0) -> Missing
A32: Audience | B32: size_companies | C32: The Estimated or actual count of Companies that form this audience. *Company Granularity to be determined | O32: =_xlfn.XLOOKUP(Table1[[#This Row],[Name]],'Field name checks'!A:A,'Field name checks'!A:A,"Missing",0) -> Missing
A33: Campaigns | B33: campaign_id | C33: Primary Identified for a campaign, This could either be the Monday code or a GCP generated ID, using the Monday code as a proxy identifier. | F33: ID - PK | J33: MVP | O33: =_xlfn.XLOOKUP(Table1[[#This Row],[Name]],'Field name checks'!A:A,'Field name checks'!A:A,"Missing",0) -> campaign_id
A34: Campaigns | B34: campaign_name | C34: The Unique business understandable short name of the campaign. | E34: Dimension for Filter / Comparison | F34: String | J34: MVP | O34: =_xlfn.XLOOKUP(Table1[[#This Row],[Name]],'Field name checks'!A:A,'Field name checks'!A:A,"Missing",0) -> campaign_name
A35: Campaigns | B35: dmo_monday_id | C35: This is Unique identifier in the DMO board for tracking campaign creation. Also used within marketo and other systems as the campaign Identifier. | M35: 45959 | N35: Added | O35: =_xlfn.XLOOKUP(Table1[[#This Row],[Name]],'Field name checks'!A:A,'Field name checks'!A:A,"Missing",0) -> dmo_monday_id
A36: Campaigns | B36: activity_status | C36: Current build status of the activity (e.g., Not started, In progress) | E36: Hidden filter to exclude irrelevant campaings from views. | G36: Not Started; In progress; Stuck; | M36: 45959 | N36: Added | O36: =_xlfn.XLOOKUP(Table1[[#This Row],[Name]],'Field name checks'!A:A,'Field name checks'!A:A,"Missing",0) -> activity_status
A37: Campaigns | B37: marketing_lead_name | C37: Primary person responsible for the activity | E37: Dimension for Filter / Comparison | M37: 45959 | N37: Added | O37: =_xlfn.XLOOKUP(Table1[[#This Row],[Name]],'Field name checks'!A:A,'Field name checks'!A:A,"Missing",0) -> marketing_lead_name
A38: Campaigns | B38: contributer_name | C38: Additional team members contributing to the activity. | E38: Dimension for Filter | M38: 45959 | N38: Added | O38: =_xlfn.XLOOKUP(Table1[[#This Row],[Name]],'Field name checks'!A:A,'Field name checks'!A:A,"Missing",0) -> contributer_name
A39: Campaigns | B39: campaign_planned_start_date | C39: Planned Start Date of the activity. (Needs confirmation if this is correct) | E39: Dimension for Filter | M39: 45959 | N39: Added | O39: =_xlfn.XLOOKUP(Table1[[#This Row],[Name]],'Field name checks'!A:A,'Field name checks'!A:A,"Missing",0) -> campaign_planned_start_date
A40: Campaigns | B40: campaign_live_date | C40: Date the campaign First went live and it was possible for a person to interact with the campaigns content. | E40: Dimension for Filter | M40: 45959 | N40: Added | O40: =_xlfn.XLOOKUP(Table1[[#This Row],[Name]],'Field name checks'!A:A,'Field name checks'!A:A,"Missing",0) -> campaign_live_date
...

Sheet Field name checks
A1: Use Case DP Attribute Name
A2: campaign_name | B2: =_xlfn.XLOOKUP(A2,Attributes!O:O,Attributes!O:O,"Missing") -> campaign_name
A3: campaign_id | B3: =_xlfn.XLOOKUP(A3,Attributes!O:O,Attributes!O:O,"Missing") -> campaign_id
A4: dmo_monday_id | B4: =_xlfn.XLOOKUP(A4,Attributes!O:O,Attributes!O:O,"Missing") -> dmo_monday_id
A5: activity_status | B5: =_xlfn.XLOOKUP(A5,Attributes!O:O,Attributes!O:O,"Missing") -> activity_status
A6: marketing_lead_name | B6: =_xlfn.XLOOKUP(A6,Attributes!O:O,Attributes!O:O,"Missing") -> marketing_lead_name
A7: contributer_name | B7: =_xlfn.XLOOKUP(A7,Attributes!O:O,Attributes!O:O,"Missing") -> contributer_name
A8: campaign_planned_start_date | B8: =_xlfn.XLOOKUP(A8,Attributes!O:O,Attributes!O:O,"Missing") -> campaign_planned_start_date
A9: campaign_live_date | B9: =_xlfn.XLOOKUP(A9,Attributes!O:O,Attributes!O:O,"Missing") -> campaign_live_date
A10: engaged_team_name | B10: =_xlfn.XLOOKUP(A10,Attributes!O:O,Attributes!O:O,"Missing") -> engaged_team_name
A11: campaign_summary | B11: =_xlfn.XLOOKUP(A11,Attributes!O:O,Attributes!O:O,"Missing") -> campaign_summary
A12: engagement_stage_classification | B12: =_xlfn.XLOOKUP(A12,Attributes!O:O,Attributes!O:O,"Missing") -> engagement_stage_classification
A13: activity_type | B13: =_xlfn.XLOOKUP(A13,Attributes!O:O,Attributes!O:O,"Missing") -> activity_type
... A35: active_flag | B35: =_xlfn.XLOOKUP(A35,Attributes!O:O,Attributes!O:O,"Missing") -> Missing

Sheet Sheet1
A1: Activity ID | B1: Outcome ID | C1: Outcome Type | D1: Link ID | E1: Interaction | F1: Contact | G1: Company | H1: Relation Type | I1: Time Lag (Days) | K1: Weight | M1: Outcome Value | N1: Attributed Amount | P1: Sales Order Value | Q1: Sales Order Value Gross Margin | R1: Initial Contract Value | S1: Initial Contract Value Gross margin | T1: Average Revenue per Unit
A2: 1 | B2: 1 | C2: Opportunty Created | D2: a | E2: 1 | F2: 1 | G2: 1 | H2: Direct Through Order | I2: 10 | K2: 0.1 | M2: 1000 | N2: =M2*K2 -> 100
A3: 1 | B3: 2 | C3: Opportunty Won | D3: b | E3: 1 | F3: 5 | G3: 2 | H3: Through Company | I3: 200 | K3: 0.02 | M3: 250 | N3: =M3*K3 -> 5
A4: 1 | B4: 2 | C4: Opportunty Won | D4: h | E4: 2 | G4: 3 | H4: Inferred company | I4: 15 | K4: 0.6 | M4: 250 | N4: =M4*K4 -> 150
A5: 2 | B5: 1 | C5: Opportunty Created | D5: c | E5: 3 | G5: 4 | H5: Through Contact & Company | I5: 1 | K5: 0.52 | M5: 1000 | N5: =M5*K5 -> 520
A6: 3 | B6: 3 | C6: Orders | D6: d | E6: 4 | F6: 6 | G6: 5 | H6: Through Company | I6: 0 | K6: 0.1 | M6: 555 | N6: =M6*K6 -> 55.5
A7: 4 | B7: 4 | C7: Orders | D7: e | F7: 5 | G7: 6 | H7: Inferred company | I7: 256 | K7: 0.001 | M7: 789 | N7: =M7*K7 -> 0.789
A8: 5 | B8: 7 | C8: Orders | D8: f | E8: 6 | G8: 7 | H8: Through Contact & Company | I8: 24 | K8: 0.001 | M8: 5 | N8: =M8*K8 -> 0.005
A9: 8 | B9: 8 | C9: Orders | D9: g | F9: 8 | G9: 8 | H9: Direct Through Order | I9: 51 | K9: 0.001 | M9: 1000000 | N9: =M9*K9 -> 1000

Sheet Object Relationships Diagram

Sheet Aggregations and Calculations
A1: Name | B1: Dashboards | C1: Description | D1: Dependancies
A2: Total Conversions | C2: Count of desired actions (purchases, sign-ups, etc.).
A3: Conversion Rate | C3: (Conversions / Audience Size) × 100
A4: Time to Conversion | C4: Avg. days between first marketing touchpoint and conversion.
A5: Conversion Rate by Channel | C5: Conversions per channel / Total audience reached via that channel.
A6: Churn Rate | C6: (Customers Lost / Total Customers at Start of Period) × 100
A7: Marketing Impact on Churn | C7: Reduction in churn among customers exposed to marketing.
A8: Attributed Marketing Impact -
A9: Attributed Revenue per Channel | C9: Revenue from customers exposed to marketing per channel.
A10: Incremental Lift from Marketing | C10: (Conversion Rate of Exposed Group - Conversion Rate of Non-Exposed Group)
A11: Marketing Influence Score | C11: Weighted impact of different marketing touchpoints on final outcomes.
A12: Multi-Touch Attribution Value per Path | C12: Total attributed revenue divided by the % of conversions that followed a specific marketing sequence.
A13: Customer Segmentation & Behavioural Trends -
A14: Customer Lifetime Value (CLV) Banding | C14: Avg. revenue per customer over a defined period.
A15: Retention Rate by Audience Segment | C15: % of customers retained within each segment (e.g., industry, location, tenure).
A16: Most Common Engagement Paths | C16: Rank sequences of interactions that most often lead to conversion.
A17: Content Effectiveness Score | C17: Engagement rate per marketing asset (emails, ads, videos, etc.).
E18: Business Description | F18: Technical Description
A19: Outcome Timeframe | B19: All Outcomes, Product Outcomes, Audience Analysis | C19: This is the Time that the outcome is recognised by the business. Here we are interested in the Raised date for orders, For other outcomes which field to use will vary | E19: “This is the time that the outcome is recognized by the business. Here we are interested in the Raised date for orders. For other outcomes, which date field to use can vary.” | F19: Typically derived from the “raised date” (or similar) in the orders/outcomes data. Stored in a field like outcome_date or order_raised_date. Used as a filter on dashboards to constrain the timeframe of recognized outcomes.
A20: Business Segment | B20: All Outcomes, Product Outcomes, Audience Analysis, Marketing Impact, Channel Impact | C20: SMB, CPS | E20: “SMB, CPS” | F20: A categorical/lookup field indicating the segment classification for each account or lead (e.g., 'SMB', 'CPS'). Likely stored in a field like business_segment in your master account/customer table.
A21: Total Conversions | B21: ??? | C21: The Number of Accounts with Orders by the number of distinct accounts in the Audience. | D21: Orders, Distinct Accounts, Audience | E21: “The Number of Accounts with Orders by the number of distinct Accounts in the Audience.” | F21: A count of unique accounts that have placed an order divided by the total number of distinct accounts in the relevant audience. E.g., COUNT(DISTINCT account_id WHERE has_order=true) / COUNT(DISTINCT account_id). Often displayed as a raw count (“converted accounts”) or a rate (“conversion rate”).
A22: Total Outcome Order Value | B22: All Outcomes, Product Outcomes, Specific Company Analysis, Audience Analysis | C22: Sum of Total_SOV for all raised Orders | E22: “Sum of Total_SOV for all raised Orders.” | F22: Aggregates the sum of value across all orders in a given timeframe or segment. E.g., SUM(order_total_sov) from orders (filtered by timeframe).
A23: Total Outcome Customer Value Change | B23: All Outcomes, Product Outcomes, Specific Company Analysis, Audience Analysis | C23: Option 1: Value Change = Total_SOV - PREV_TOTAL_SOV Keep this for only new Renewal or changed orders. This is for the date that the new order is raised. Option 2: Value Change = Sum (Total_SOV) Where Raised date in Timeframe - Sum (Total_SOV) Where Ceased Date in Timeframe Relies on Ceased dates being correct, Also need to consider how raised but ultimately failed orders are considered. | E23: “(Option 1) Value Change = Total_SOV - PREV_TOTAL_SOV. (Option 2) Value Change = Sum(Total_SOV) where raised date in timeframe - Sum(Total_SOV) where ceased date in timeframe.” | F23: Tracks how a customer’s total service/order value changes over time (new vs. ceased). One approach is current_sov - previous_sov. Alternatively, measure new SOV raised minus SOV ceased in the timeframe. Store or compute from orders data (raised_date, ceased_date).
A24: Total Outcome Churn | B24: All Outcomes, Product Outcomes, Specific Company Analysis, Audience Analysis | C24: Churn could be at 3 levels Customer, Product Group, Specific Product. Specific Product Option 1: For a Customer (Billing Account Level) A churn on a date occurs when on the previous day there was at least on active product for that customer. But on the selected day there are no longer any active products for the particular product specified. Products that cease but there exists another product that is linked as a renewal even if its a different product. Would not count as a product level churn. Product Family As Above but here looking at all product for a customer within a product family, If the count of live products for a product family for a customer goes from 1>0 This is a churn event for this customer (BAN). Again exclude from this products where there is a linked renewal for a product even if in a different family. Customer For a customer (BAN) a Churn occurs on a date where the count of live products goes from 1>0. Outstanding Questions: - Which is the field for the ceased date | E24: “Churn could be at 3 levels: Customer, Product Group, Specific Product. A churn event occurs on a date if the count of live products goes from 1→0 with no renewal link.” | F24: You can measure churn events/amount by comparing active product records day-to-day. E.g., a product is “ceased” on date X if it was active the prior day. Product-level or family-level churn excludes renewals. Technically, you might store churn_date or compare active_product_count from t to t-1.
A25: Attributed Outcome Order Value Amount | B25: All Outcomes, Product Outcomes, Specific Company Analysis, Audience Analysis, Marketing Impact, Channel Impact, Campaign Impact, Marketing Technology Impact | C25: Sum (Total_SOV for raised orders * Attribute %) Apply the attributed Percentage reduction to each raised order then Sum these. | E25: “Sum (Total_SOV for raised orders * Attribute %). Apply the attributed percentage to each raised order, then sum.” | F25: For each order, multiply its order_value (Total_SOV) by the marketing attribution factor (e.g., 0.3 if 30% is attributed to marketing). Then sum across all orders in the timeframe or segment. Technically: SUM(order_value * marketing_attribution_pct).
A26: Attributed Outcome Order Value Percentage | B26: All Outcomes, Product Outcomes, Specific Company Analysis, Audience Analysis, Marketing Impact, Channel Impact, Campaign Impact, Marketing Technology Impact | C26: Aggregated (Attributed Outcome order values amount) / Agreegated (Outcome order value amount) This is likely to be different to the sum of the attributed percentages. As it might be that larger orders have a larger marketing attribution and so the total amount attributed to marketing is higher once order values are taken into account. Here the order value could be any of SOV, SOV_GM, ICV, ICV_GM. Suggest the dashboard has some sort of switcher to move between these. | E26: (Percentage of total order value that is attributed to marketing.) | F26: Calculated as (Attributed Outcome Order Value Amount / Total Outcome Order Value) * 100. For a given dimension or grouping, you might do: SUM(order_value * attribution_pct) / SUM(order_value) * 100.
A27: Attributed Outcome Customer Value Change £ | B27: All Outcomes, Product Outcomes, Specific Company Analysis, Audience Analysis, Marketing Impact, Channel Impact, Campaign Impact, Marketing Technology Impact | E27: (Similar to “Customer Value Change,” but restricted to the fraction attributed to marketing.) | F27: For each relevant account or order, take the “value change” and multiply by the attribution factor. E.g., SUM( (new_sov - old_sov) * marketing_attribution_pct ) for the relevant set of records.
A28: Attributed Outcome Customer Value Change Percentage | B28: All Outcomes, Product Outcomes, Specific Company Analysis, Audience Analysis, Marketing Impact, Channel Impact, Campaign Impact, Marketing Technology Impact | E28: (Ratio of marketing-attributed customer value change to total customer value change.) | F28: (Attributed Outcome Customer Value Change £ / Total Outcome Customer Value Change) * 100.
A29: Attributed Outcome Churn | B29: All Outcomes, Product Outcomes, Specific Company Analysis, Audience Analysis, Marketing Impact, Channel Impact, Campaign Impact, Marketing Technology Impact | E29: “Churn could be at 3 levels… and we apply marketing attribution factor (or logic) to see which portion is attributed to marketing.” | F29: If marketing is credited with preventing or partially causing churn, you might track the fraction of churn events or churn amounts “tied” to marketing. The exact logic depends on your attribution model—e.g., if marketing prevented churn, or if a missed marketing touch contributed to churn. This is more specialized and may or may not appear on the Channel/Campaign dashboards unless explicitly needed.
A30: Attributed Outcome Churn Percentage | B30: All Outcomes, Product Outcomes, Specific Company Analysis, Audience Analysis, Marketing Impact, Channel Impact, Campaign Impact, Marketing Technology Impact | E30: (Percentage of total churn that was attributed to marketing, or possibly the share that was prevented by marketing.) | F30: Computed similarly to “Attributed Outcome Churn,” but expressed as a percentage: (Attributed Churn / Total Churn) * 100, or “churn avoided.” Not explicitly listed in Channel/Campaign/Tech dashboards in the PPT, so typically remains in the “outcomes” or “audience” views.
A31: Marketing Activity Channel group | B31: All Outcomes, Product Outcomes, Specific Company Analysis, Audience Analysis, Marketing Impact, Channel Impact, Campaign Impact, Marketing Technology Impact | C31: Web, Social, Outbound Comms | E31: “Web, Social, Outbound Comms,” etc. | F31: A high-level grouping of channels used for marketing. Often stored in a dimension table or a field like channel_group (e.g., 'web', 'social', 'outbound'). Widely used across multiple dashboards as a dimension or filter.
A32: Marketing Activity Channel | B32: Product Outcomes, Marketing Impact, Channel Impact, Campaign Impact, Marketing Technology Impact | E32: (A more granular channel—e.g., Email, Paid Search, LinkedIn Ads, etc.) | F32: A detailed channel field in your campaign/activity logs, e.g., marketing_channel = 'email'. In your dashboards, you might roll this up into “channel group.”
A33: Outcome Product Family | B33: All Outcomes, Product Outcomes,Channel Impact | E33: (Groups outcome products into families—e.g., Mobile, Broadband, Security, etc.) | F33: A categorical or lookup field that classifies products. Typically in a product dimension table: product_family_id → 'Mobile', 'Hosting', 'Security', etc. Seen in multiple “outcome-focused” dashboards and also in Channel Impact (the PPT specifically references “Product Families” as a dimension).
A34: Outcome Product | B34: Product Outcomes, Specific Company Analysis, Channel Impact, Campaign Impact | E34: (The specific product sold, renewed, or churned.) | F34: Typically references the exact product in the outcome. E.g., a field outcome_product_id or order_product_code. Displayed in product-level dashboards, or in the “outcome products” dimension for Channel/Campaign Impact.
A35: Campaign Product Family | B35: Marketing Impact, Channel Impact | E35: (Indicates which product family the campaign is targeting or associated with—e.g., a “Mobile” campaign.) | F35: A lookup from the campaign record to the targeted product family. E.g., campaign_target_product_family_id → 'Mobile'. Explicitly in Marketing Impact and Channel Impact; can also be relevant in Campaign Impact or Tech Impact if you want to see the product families each campaign aims at.
A36: Transactions Channel | B36: All Outcomes, Product Outcomes | C36: How did they transact the order | E36: “How did they transact the order?” (online, phone, in-person, etc.) | F36: A field in the order data indicating the fulfillment/purchase channel. Often called something like transaction_channel. The PPT references “transactions channel” especially in outcome-focused dashboards.
A37: Outcome Type | B37: All Outcomes, Product Outcomes | C37: Acquisition, Resign, Cross-Sell | E37: “Acquisition, Resign, Cross-Sell.” | F37: A categorical field describing the type of outcome event. E.g., 'acquisition', 'resign', 'cross_sell'. Typically stored in outcome_type.
A38: Outcome Intentionality - Product | B38: All Outcomes, Product Outcomes | C38: *Did outcome product match marketing target product | E38: “Did the outcome product match the marketing target product?” | F38: A boolean or categorical field indicating if the actual product purchased (outcome) aligns with the intended product from the campaign. E.g.: outcome_product_id == campaign_target_product_id.
A39: Outcome Intentionality - Outcome Type | B39: All Outcomes, Product Outcomes | E39: (Checks if the type of outcome matched the intended outcome type—e.g., an Acquisition campaign yields an Acquisition outcome.) | F39: Another boolean or categorical field indicating if the outcome type (e.g., cross-sell) matches the campaign’s intended type. E.g.: IF campaign_objective = 'Cross-sell' AND outcome_type = 'cross_sell' THEN 'Intentional' ELSE 'Not Intentional'.
A40: Number of Campaigns | B40: Product Outcomes, Marketing Impact, Channel Impact, Marketing Technology Impact | E40: (A count of how many distinct campaigns were run or influenced the selected outcomes/timeframe.) | F40: Computed by counting distinct campaign_id across all relevant records. E.g.: COUNT(DISTINCT campaign_id). PPT explicitly mentions “# of campaigns run” in Product Outcomes, Marketing Impact, Channel Impact, and Marketing Technology dashboards.
...

Sheet Channels
A1: channel_id | B1: channel_name | C1: channel_group | D1: Identifiable method | E1: type | F1: Comment | G1: communication_mode | H1: Interaction Types | I1: POC | J1: Interaction Data Source | K1: GCP Data Availability
B2: Paid Digital Ads | C2: ATL | D2: IP Inferred | E2: Digital | G2: Pull | H2: =_xlfn.XLOOKUP(B2,Table2[Channel Name],Table2[Interactions Concatenated],"",0,1) -> Viewed;Clicked;Submit Form | J2: EssenceMediacom | K2: Data source unknown
B3: Content Syndication | C3: ATL | D3: Audience Inferred | E3: Digital | G3: Pull | H3: =_xlfn.XLOOKUP(B3,Table2[Channel Name],Table2[Interactions Concatenated],"",0,1) -> Viewed;Clicked;Submit Form
B4: Web | C4: ATL | D4: IP Inferred or Better | E4: Digital | G4: Pull | H4: =_xlfn.XLOOKUP(B4,Table2[Channel Name],Table2[Interactions Concatenated],"",0,1) -> Page View;Link Click;Submit Form;Watch Video;Download;Live Chat? | J4: Adobe web/app visits | K4: Data sources are knows, exists partially in CCN
B5: Above the Line - Non Digital | C5: ATL | D5: Audience Inferred | E5: Physical | F5: Placeholder For multiple channels | G5: Pull | H5: =_xlfn.XLOOKUP(B5,Table2[Channel Name],Table2[Interactions Concatenated],"",0,1) -> Viewed
B6: Social Posts | C6: ATL | D6: Audience Inferred | E6: Digital | G6: Pull | H6: =_xlfn.XLOOKUP(B6,Table2[Channel Name],Table2[Interactions Concatenated],"",0,1) -> Viewed;Clicked;Responded
B7: Social Outbound Messages | C7: BTL | D7: Known Person | E7: Digital | G7: Push | H7: =_xlfn.XLOOKUP(B7,Table2[Channel Name],Table2[Interactions Concatenated],"",0,1) -> Viewed;Clicked;Responded;Opt-Out
B8: Virtual Events | C8: BTL | D8: Self Identified | E8: Events | G8: Push | H8: =_xlfn.XLOOKUP(B8,Table2[Channel Name],Table2[Interactions Concatenated],"",0,1) -> Registered;Attended;View on Demand
B9: F2F Events | C9: BTL | D9: Self Identified | E9: Events | G9: Push | H9: =_xlfn.XLOOKUP(B9,Table2[Channel Name],Table2[Interactions Concatenated],"",0,1) -> Registered;Attended
B10: Webinars | C10: BTL | D10: Self Identified | E10: Events | H10: =_xlfn.XLOOKUP(B10,Table2[Channel Name],Table2[Interactions Concatenated],"",0,1) -> Registered;Attended;View on Demand
B11: Direct Mail | C11: BTL | D11: Known Person | E11: Physical | H11: =_xlfn.XLOOKUP(B11,Table2[Channel Name],Table2[Interactions Concatenated],"",0,1) -> Sent;Received;Bounced | I11: TRUE
B12: Whatsapp | C12: BTL | D12: Known Person | E12: Digital | H12: =_xlfn.XLOOKUP(B12,Table2[Channel Name],Table2[Interactions Concatenated],"",0,1) -> Sent;Received;Read;Clicked;Responded;Opt-Out
B13: RCS | C13: BTL | D13: Known Person | E13: Digital | H13: =_xlfn.XLOOKUP(B13,Table2[Channel Name],Table2[Interactions Concatenated],"",0,1) -> Sent;Received;Read;Clicked;Responded;Opt-Out;Opened
B14: Email | C14: BTL | D14: Known Person | E14: Digital | H14: =_xlfn.XLOOKUP(B14,Table2[Channel Name],Table2[Interactions Concatenated],"",0,1) -> Sent;Received;Bounced;Opened;Clicked;Opt-Out;Responded | I14: TRUE | J14: Marketo email activities | K14: Data sources are known, exists in GCP CCN
B15: SMS | C15: BTL | D15: Known Person | E15: Digital | H15: =_xlfn.XLOOKUP(B15,Table2[Channel Name],Table2[Interactions Concatenated],"",0,1) -> Sent;Received;Bounced;Clicked;Responsed;Opt-Out | I15: TRUE | J15: IMI | K15: Data does not exist in GCP
B16: MMS | C16: BTL | D16: Known Person | E16: Digital | H16: =_xlfn.XLOOKUP(B16,Table2[Channel Name],Table2[Interactions Concatenated],"",0,1) -> Sent;Received;Bounced;Clicked;Responsed;Opt-Out
B17: App Push Notification | C17: BTL | D17: Known Person | E17: Digital | H17: =_xlfn.XLOOKUP(B17,Table2[Channel Name],Table2[Interactions Concatenated],"",0,1) -> Sent;Received;Clicked
B18: Telemarketing | C18: BTL | D18: Known Person | E18: Conversation | H18: =_xlfn.XLOOKUP(B18,Table2[Channel Name],Table2[Interactions Concatenated],"",0,1) -> Attempted;Answered;Conversed | J18: NRT | K18: Data sources are known, exists in GCP CCN
B19: Online Chat | C19: BTL | D19: Self Identified / IP Inferred | E19: Conversation | H19: =_xlfn.XLOOKUP(B19,Table2[Channel Name],Table2[Interactions Concatenated],"",0,1) -> Initiated;Answered;Disconnected | J19: NRT | K19: Data sources are known, exists in GCP CCN
B20: Salesperson Meetings | C20: Sales | D20: Known Person | E20: Conversation | H20: =_xlfn.XLOOKUP(B20,Table2[Channel Name],Table2[Interactions Concatenated],"",0,1) -> Invited;Attended
B21: Salesperson Calls | C21: Sales | D21: Known Person | E21: Conversation | H21: =_xlfn.XLOOKUP(B21,Table2[Channel Name],Table2[Interactions Concatenated],"",0,1) -> Dialled;Answered;Engaged
B22: Salesperson Email | C22: Sales | D22: Known Person | E22: Digital | H22: =_xlfn.XLOOKUP(B22,Table2[Channel Name],Table2[Interactions Concatenated],"",0,1) -> Sent;Received;Bounced;Opened;Clicked;Opt-Out;Responded
B23: Inbound Calls | C23: BTL | D23: Known Person | E23: Conversation | G23: Pull | H23: =_xlfn.XLOOKUP(B23,Table2[Channel Name],Table2[Interactions Concatenated],"",0,1) -> Called;Not Answered | J23: NRT | K23: Data sources are known, exists in GCP CCN

Sheet Interaction Types
A1: Channel Name | B1: Interactions Concatenated | C1: Interactions | D1: Column1 | E1: Column2 | F1: Column3 | G1: Column4 | H1: Column5 | I1: Column6
A2: Above the Line - Non Digital | B2: =_xlfn.TEXTJOIN(";",TRUE,C2:I2) -> Viewed | C2: Viewed
A3: App Push Notification | B3: =_xlfn.TEXTJOIN(";",TRUE,C3:I3) -> Sent;Received;Clicked | C3: Sent | D3: Received | F3: Clicked
A4: Content Syndication | B4: =_xlfn.TEXTJOIN(";",TRUE,C4:I4) -> Viewed;Clicked;Submit Form | C4: Viewed | D4: Clicked | E4: Submit Form
A5: Direct Mail | B5: =_xlfn.TEXTJOIN(";",TRUE,C5:I5) -> Sent;Received;Bounced | C5: Sent | D5: Received | E5: Bounced
A6: Email | B6: =_xlfn.TEXTJOIN(";",TRUE,C6:I6) -> Sent;Received;Bounced;Opened;Clicked;Opt-Out;Responded | C6: Sent | D6: Received | E6: Bounced | F6: Opened | G6: Clicked | H6: Opt-Out | I6: Responded
A7: F2F Events | B7: =_xlfn.TEXTJOIN(";",TRUE,C7:I7) -> Registered;Attended | C7: Registered | D7: Attended
A8: Inbound Calls | B8: =_xlfn.TEXTJOIN(";",TRUE,C8:I8) -> Called;Not Answered | C8: Called | D8: Not Answered
A9: MMS | B9: =_xlfn.TEXTJOIN(";",TRUE,C9:I9) -> Sent;Received;Bounced;Clicked;Responsed;Opt-Out | C9: Sent | D9: Received | E9: Bounced | F9: Clicked | G9: Responsed | H9: Opt-Out
A10: Online Chat | B10: =_xlfn.TEXTJOIN(";",TRUE,C10:I10) -> Initiated;Answered;Disconnected | C10: Initiated | D10: Answered | E10: Disconnected
A11: Paid Digital Ads | B11: =_xlfn.TEXTJOIN(";",TRUE,C11:I11) -> Viewed;Clicked;Submit Form | C11: Viewed | D11: Clicked | E11: Submit Form
A12: RCS | B12: =_xlfn.TEXTJOIN(";",TRUE,C12:I12) -> Sent;Received;Read;Clicked;Responded;Opt-Out;Opened | C12: Sent | D12: Received | E12: Read | F12: Clicked | G12: Responded | H12: Opt-Out | I12: Opened
A13: Salesperson Calls | B13: =_xlfn.TEXTJOIN(";",TRUE,C13:I13) -> Dialled;Answered;Engaged | C13: Dialled | D13: Answered | E13: Engaged
A14: Salesperson Email | B14: =_xlfn.TEXTJOIN(";",TRUE,C14:I14) -> Sent;Received;Bounced;Opened;Clicked;Opt-Out;Responded | C14: Sent | D14: Received | E14: Bounced | F14: Opened | G14: Clicked | H14: Opt-Out | I14: Responded
A15: Salesperson Meetings | B15: =_xlfn.TEXTJOIN(";",TRUE,C15:I15) -> Invited;Attended | C15: Invited | D15: Attended
A16: SMS | B16: =_xlfn.TEXTJOIN(";",TRUE,C16:I16) -> Sent;Received;Bounced;Clicked;Responsed;Opt-Out | C16: Sent | D16: Received | E16: Bounced | F16: Clicked | G16: Responsed | H16: Opt-Out
A17: Social Outbound Messages | B17: =_xlfn.TEXTJOIN(";",TRUE,C17:I17) -> Viewed;Clicked;Responded;Opt-Out | C17: Viewed | D17: Clicked | E17: Responded | F17: Opt-Out
A18: Social Posts | B18: =_xlfn.TEXTJOIN(";",TRUE,C18:I18) -> Viewed;Clicked;Responded | C18: Viewed | D18: Clicked | E18: Responded
A19: Telemarketing | B19: =_xlfn.TEXTJOIN(";",TRUE,C19:I19) -> Attempted;Answered;Conversed | C19: Attempted | D19: Answered | E19: Conversed
A20: Virtual Events | B20: =_xlfn.TEXTJOIN(";",TRUE,C20:I20) -> Registered;Attended;View on Demand | C20: Registered | D20: Attended | E20: View on Demand
A21: Web | B21: =_xlfn.TEXTJOIN(";",TRUE,C21:I21) -> Page View;Link Click;Submit Form;Watch Video;Download;Live Chat? | C21: Page View | D21: Link Click | E21: Submit Form | F21: Watch Video | G21: Download | H21: Live Chat?
A22: Webinars | B22: =_xlfn.TEXTJOIN(";",TRUE,C22:I22) -> Registered;Attended;View on Demand | C22: Registered | D22: Attended | E22: View on Demand
A23: Whatsapp | B23: =_xlfn.TEXTJOIN(";",TRUE,C23:I23) -> Sent;Received;Read;Clicked;Responded;Opt-Out | C23: Sent | D23: Received | E23: Read | F23: Clicked | G23: Responded | H23: Opt-Out
